Workbook
Name BT: Sheet1!$AI$1315

Sheet Sheet1
A1: Date | B1: FIBCF_Nifty_100 | C1: Franklin_Nifty_50_TRI | D1: FIFCF Nifty 500 TRI | E1: FIOF Nifty 500 TRI | F1: FIT Nifty 500 TRI | G1: Franklin Nifty LargeMidCap 250 TRI Adj Values | H1: Franklin_Nifty Midcap 150 TRI_Adj | I1: Franklin_Nifty Smallcap 250 TRI_Adj | J1: Franklin SP BSE 500 TRI | K1: FITF BSE Teck | L1: TIEIF Nifty 500 Adj | M1: TIVF Nifty 500 Adj | N1: FUSOF Russell 3000 | O1: FUSOF SP 500 TRI | P1: Franklin_BSE_India_Infrastructure | Q1: FIDAAF CRISIL Hybrid3565-Aggressive Index | R1: FIEHF CRISIL Hybrid 35 65 - Aggressive Index | S1: FIMAS CRISIL Hybrid3565-Aggressive Index | T1: Franklin_Nifty_Equity_Savings_Index | U1: FIONF_NIFTY 1D Rate Index | V1: FILF NIFTY Liquid Index A-I | W1: FISF NIFTY Money Market Index A-I | X1: FICDF NIFTY Corporate Bond Index A-II | Y1: FIFRF_NIFTY Short Duration Debt Index A-II | Z1: Franklin Nifty Banking and PSU Debt Index A-II | AA1: FIPEP Custom | AB1: FIBAF_NIFTY 50 Hybrid Composite Debt 50 50 Index | AC1: Franklin_CRISIL Long Duration Debt A-III Index | AD1: Franklin_CRISIL Medium to Long Duration Debt A-III Index | AE1: Franklin_NIFTY Low Duration Debt Index A-I | AF1: Franklin_NIFTY Ultra Short Duration Debt Index A-I | AG1: FIIOF Nifty Medium Duration Custom Index | AH1: FIONF_CRISIL Overnight Index | AI1: Franklin NIFTY Money Market Index | AJ1: Franklin NIFTY Ultra Short Duration Debt Index_Adj values | AK1: Franklin_CRISIL_Hybrid_8515_Conservative_Index | AL1: Franklin_CRISIL_10_Year_Gilt_Index | AM1: Franklin_NIFTY All Duration G-Sec Index Adj | AN1: Franklin_CRISIL_1_Year_T-Bill_Index | AO1: Franklin_GOLD_INR_Ounce | AP1: Franklin_FIBCF_Adj_NAV | AQ1: Franklin_TIGF-Div(Adj NAV) | AR1: FITF Adj NAV | AS1: Franklin_FIPAF | AT1: FAEF MSCI Asia Ex-Japan Nifty 500 | AU1: FISF NIFTY Money Market Index A-I | AV1: FILF CRISIL Liquid Fund AI Index | AW1: FIDAAF Adj CRISIL Hybrid 5050 Moderate Index | AX1: Franklin_FIMAAF | AZ1: CRISIL 10 Year Gilt Index | BA1: CRISIL Hybrid 35+65 - Aggressive Index | BB1: CRISIL Hybrid 85+15 - Conservative Index | BC1: I-Sec Li- BEX | BD1: NIFTY Banking & PSU Debt Index | BE1: NIFTY Corporate Bond Index | BF1: NIFTY Credit Risk Bond Index | BG1: NIFTY Equity Savings Index | BH1: NIFTY Low Duration Debt Index | BI1: NIFTY Medium Duration Debt Index | BJ1: NIFTY Medium to Long Duration Debt Index | BK1: NIFTY Money Market Index A-I | BL1: NIFTY Ultra Short Duration Debt Index | BM1: CRISIL 1 Year T-Bill Index | BN1: CRISIL Overnight Index | BO1: NIFTY All Duration G-Sec Index | BP1: CRISIL Low Duration Debt Index | BS1: NIFTY 1D Rate Index | BT1: NIFTY Liquid Index A-I | BU1: NIFTY Money Market Index A-I | BV1: NIFTY Corporate Bond Index A-II | BW1: NIFTY Short Duration Debt Index A-II | BX1: NIFTY Banking & PSU Debt Index A-II | BY1: CRISIL Short Term Debt Hybrid 60+40 Index | BZ1: NIFTY 50 Hybrid Composite Debt 50:50 Index | CA1: CRISIL Long Duration Debt A-III Index | CB1: CRISIL Medium to Long Duration Debt A-III Index | CC1: NIFTY Low Duration Debt Index A-I | CD1: NIFTY Ultra Short Duration Debt Index A-I
A2: 44287 | B2: 19535.92 | C2: 21137.69 | D2: 18968.55 | E2: 18968.55 | F2: 18968.55 | G2: 9994.66 | H2: 11225.99 | I2: 8697.4 | J2: 24128.536 | K2: 14935.955 | N2: 970316.4 | O2: =VLOOKUP(A2,'[1]FUSOF AD'!$A:$D,4,0) | Q2: =VLOOKUP(BA$1&$A2,Sheet2!$A:$D,4,0) | R2: =VLOOKUP(BA$1&$A2,Sheet2!$A:$D,4,0) | S2: =VLOOKUP(BA$1&$A2,Sheet2!$A:$D,4,0) | T2: =VLOOKUP(BG$1&$A2,Sheet2!$A:$D,4,0) | AG2: =VLOOKUP(BI$1&$A2,Sheet2!$A:$D,4,0) | AH2: =VLOOKUP(BN$1&$A2,Sheet2!$A:$D,4,0) | AI2: =VLOOKUP(BK$1&$A2,Sheet2!$A:$D,4,0) | AJ2: =VLOOKUP(BL$1&$A2,Sheet2!$A:$D,4,0) | AK2: =VLOOKUP(BB$1&$A2,Sheet2!$A:$D,4,0) | AL2: =VLOOKUP(AZ$1&$A2,Sheet2!$A:$D,4,0) | AN2: =VLOOKUP(BM$1&$A2,Sheet2!$A:$D,4,0) | AO2: 126862.13 | AP2: 1450.3243 | AQ2: 356.53094 | AR2: 562.70236
A3: 44291 | B3: 19252.94 | C3: 20811.61 | D3: 18694.76 | E3: 18694.76 | F3: 18694.76 | G3: 9854.26 | H3: 11073.12 | I3: 8559.56 | J3: 23780.797 | K3: 15184.883 | N3: 984671.08 | O3: =VLOOKUP(A3,'[1]FUSOF AD'!$A:$D,4,0) | Q3: =VLOOKUP(BA$1&$A3,Sheet2!$A:$D,4,0) | R3: =VLOOKUP(BA$1&$A3,Sheet2!$A:$D,4,0) | S3: =VLOOKUP(BA$1&$A3,Sheet2!$A:$D,4,0) | T3: =VLOOKUP(BG$1&$A3,Sheet2!$A:$D,4,0) | AG3: =VLOOKUP(BI$1&$A3,Sheet2!$A:$D,4,0) | AH3: =VLOOKUP(BN$1&$A3,Sheet2!$A:$D,4,0) | AI3: =VLOOKUP(BK$1&$A3,Sheet2!$A:$D,4,0) | AJ3: =VLOOKUP(BL$1&$A3,Sheet2!$A:$D,4,0) | AK3: =VLOOKUP(BB$1&$A3,Sheet2!$A:$D,4,0) | AL3: =VLOOKUP(AZ$1&$A3,Sheet2!$A:$D,4,0) | AN3: =VLOOKUP(BM$1&$A3,Sheet2!$A:$D,4,0) | AO3: 126684.27 | AP3: 1420.9388 | AQ3: 350.33998 | AR3: 571.16491
A4: 44292 | B4: 19331.85 | C4: 20876.57 | D4: 18785.23 | E4: 18785.23 | F4: 18785.23 | G4: 9905.93 | H4: 11143.71 | I4: 8651.91 | J4: 23893.374 | K4: 15218.486 | N4: 986097.28 | O4: =VLOOKUP(A4,'[1]FUSOF AD'!$A:$D,4,0) | Q4: =VLOOKUP(BA$1&$A4,Sheet2!$A:$D,4,0) | R4: =VLOOKUP(BA$1&$A4,Sheet2!$A:$D,4,0) | S4: =VLOOKUP(BA$1&$A4,Sheet2!$A:$D,4,0) | T4: =VLOOKUP(BG$1&$A4,Sheet2!$A:$D,4,0) | AG4: =VLOOKUP(BI$1&$A4,Sheet2!$A:$D,4,0) | AH4: =VLOOKUP(BN$1&$A4,Sheet2!$A:$D,4,0) | AI4: =VLOOKUP(BK$1&$A4,Sheet2!$A:$D,4,0) | AJ4: =VLOOKUP(BL$1&$A4,Sheet2!$A:$D,4,0) | AK4: =VLOOKUP(BB$1&$A4,Sheet2!$A:$D,4,0) | AL4: =VLOOKUP(AZ$1&$A4,Sheet2!$A:$D,4,0) | AN4: =VLOOKUP(BM$1&$A4,Sheet2!$A:$D,4,0) | AO4: 128127.98 | AP4: 1420.9477 | AQ4: 349.91484 | AR4: 573.25259
A5: 44293 | B5: 19511.28 | C5: 21069.32 | D5: 18972.6 | E5: 18972.6 | F5: 18972.6 | G5: 10012.04 | H5: 11278.77 | I5: 8772.24 | J5: 24131.865 | K5: 15383.584 | N5: 1002584.6 | O5: =VLOOKUP(A5,'[1]FUSOF AD'!$A:$D,4,0) | Q5: =VLOOKUP(BA$1&$A5,Sheet2!$A:$D,4,0) | R5: =VLOOKUP(BA$1&$A5,Sheet2!$A:$D,4,0) | S5: =VLOOKUP(BA$1&$A5,Sheet2!$A:$D,4,0) | T5: =VLOOKUP(BG$1&$A5,Sheet2!$A:$D,4,0) | AG5: =VLOOKUP(BI$1&$A5,Sheet2!$A:$D,4,0) | AH5: =VLOOKUP(BN$1&$A5,Sheet2!$A:$D,4,0) | AI5: =VLOOKUP(BK$1&$A5,Sheet2!$A:$D,4,0) | AJ5: =VLOOKUP(BL$1&$A5,Sheet2!$A:$D,4,0) | AK5: =VLOOKUP(BB$1&$A5,Sheet2!$A:$D,4,0) | AL5: =VLOOKUP(AZ$1&$A5,Sheet2!$A:$D,4,0) | AN5: =VLOOKUP(BM$1&$A5,Sheet2!$A:$D,4,0) | AO5: 129170.24 | AP5: 1437.6979 | AQ5: 353.98453 | AR5: 580.24474
A6: 44294 | B6: 19594.26 | C6: 21149.59 | D6: 19065.82 | E6: 19065.82 | F6: 19065.82 | G6: 10063.49 | H6: 11346.52 | I6: 8865.73 | J6: 24251.144 | K6: 15527.156 | N6: 1013988.2 | O6: =VLOOKUP(A6,'[1]FUSOF AD'!$A:$D,4,0) | Q6: =VLOOKUP(BA$1&$A6,Sheet2!$A:$D,4,0) | R6: =VLOOKUP(BA$1&$A6,Sheet2!$A:$D,4,0) | S6: =VLOOKUP(BA$1&$A6,Sheet2!$A:$D,4,0) | T6: =VLOOKUP(BG$1&$A6,Sheet2!$A:$D,4,0) | AG6: =VLOOKUP(BI$1&$A6,Sheet2!$A:$D,4,0) | AH6: =VLOOKUP(BN$1&$A6,Sheet2!$A:$D,4,0) | AI6: =VLOOKUP(BK$1&$A6,Sheet2!$A:$D,4,0) | AJ6: =VLOOKUP(BL$1&$A6,Sheet2!$A:$D,4,0) | AK6: =VLOOKUP(BB$1&$A6,Sheet2!$A:$D,4,0) | AL6: =VLOOKUP(AZ$1&$A6,Sheet2!$A:$D,4,0) | AN6: =VLOOKUP(BM$1&$A6,Sheet2!$A:$D,4,0) | AO6: 130943.95 | AP6: 1442.1492 | AQ6: 354.40245 | AR6: 586.22675
A7: 44295 | B7: 19552.55 | C7: 21094.17 | D7: 19044.22 | E7: 19044.22 | F7: 19044.22 | G7: 10060.49 | H7: 11363.52 | I7: 8913.35 | J7: 24225.033 | K7: 15592.764 | N7: 1024409 | O7: =VLOOKUP(A7,'[1]FUSOF AD'!$A:$D,4,0) | Q7: =VLOOKUP(BA$1&$A7,Sheet2!$A:$D,4,0) | R7: =VLOOKUP(BA$1&$A7,Sheet2!$A:$D,4,0) | S7: =VLOOKUP(BA$1&$A7,Sheet2!$A:$D,4,0) | T7: =VLOOKUP(BG$1&$A7,Sheet2!$A:$D,4,0) | AG7: =VLOOKUP(BI$1&$A7,Sheet2!$A:$D,4,0) | AH7: =VLOOKUP(BN$1&$A7,Sheet2!$A:$D,4,0) | AI7: =VLOOKUP(BK$1&$A7,Sheet2!$A:$D,4,0) | AJ7: =VLOOKUP(BL$1&$A7,Sheet2!$A:$D,4,0) | AK7: =VLOOKUP(BB$1&$A7,Sheet2!$A:$D,4,0) | AL7: =VLOOKUP(AZ$1&$A7,Sheet2!$A:$D,4,0) | AN7: =VLOOKUP(BM$1&$A7,Sheet2!$A:$D,4,0) | AO7: 130247.92 | AP7: 1435.2557 | AQ7: 352.95308 | AR7: 587.97959
A8: 44298 | B8: 18830.49 | C8: 20348.99 | D8: 18279.05 | E8: 18279.05 | F8: 18279.05 | G8: 9613.4 | H8: 10775.19 | I8: 8432.69 | J8: 23248.266 | K8: 15198.232 | N8: 1028107 | O8: =VLOOKUP(A8,'[1]FUSOF AD'!$A:$D,4,0) | Q8: =VLOOKUP(BA$1&$A8,Sheet2!$A:$D,4,0) | R8: =VLOOKUP(BA$1&$A8,Sheet2!$A:$D,4,0) | S8: =VLOOKUP(BA$1&$A8,Sheet2!$A:$D,4,0) | T8: =VLOOKUP(BG$1&$A8,Sheet2!$A:$D,4,0) | AG8: =VLOOKUP(BI$1&$A8,Sheet2!$A:$D,4,0) | AH8: =VLOOKUP(BN$1&$A8,Sheet2!$A:$D,4,0) | AI8: =VLOOKUP(BK$1&$A8,Sheet2!$A:$D,4,0) | AJ8: =VLOOKUP(BL$1&$A8,Sheet2!$A:$D,4,0) | AK8: =VLOOKUP(BB$1&$A8,Sheet2!$A:$D,4,0) | AL8: =VLOOKUP(AZ$1&$A8,Sheet2!$A:$D,4,0) | AN8: =VLOOKUP(BM$1&$A8,Sheet2!$A:$D,4,0) | AO8: 129903.88 | AP8: 1379.8475 | AQ8: 335.95072 | AR8: 577.64999
A9: 44299 | B9: 19077.2 | C9: 20624.86 | D9: 18526.24 | E9: 18526.24 | F9: 18526.24 | G9: 9744.99 | H9: 10928.91 | I9: 8574.17 | J9: 23567.782 | K9: 14885.971 | N9: 1043027.1 | O9: =VLOOKUP(A9,'[1]FUSOF AD'!$A:$D,4,0) | Q9: =VLOOKUP(BA$1&$A9,Sheet2!$A:$D,4,0) | R9: =VLOOKUP(BA$1&$A9,Sheet2!$A:$D,4,0) | S9: =VLOOKUP(BA$1&$A9,Sheet2!$A:$D,4,0) | T9: =VLOOKUP(BG$1&$A9,Sheet2!$A:$D,4,0) | AG9: =VLOOKUP(BI$1&$A9,Sheet2!$A:$D,4,0) | AH9: =VLOOKUP(BN$1&$A9,Sheet2!$A:$D,4,0) | AI9: =VLOOKUP(BK$1&$A9,Sheet2!$A:$D,4,0) | AJ9: =VLOOKUP(BL$1&$A9,Sheet2!$A:$D,4,0) | AK9: =VLOOKUP(BB$1&$A9,Sheet2!$A:$D,4,0) | AL9: =VLOOKUP(AZ$1&$A9,Sheet2!$A:$D,4,0) | AN9: =VLOOKUP(BM$1&$A9,Sheet2!$A:$D,4,0) | AO9: 131240.63 | AP9: 1405.5046 | AQ9: 344.48191 | AR9: 572.08363
A10: 44301 | B10: 19181.27 | C10: 20733.88 | D10: 18603.68 | E10: 18603.68 | F10: 18603.68 | G10: 9773.07 | H10: 10932.56 | I10: 8547.05 | J10: 23665.857 | K10: 14906.544 | N10: 1043380.7 | O10: =VLOOKUP(A10,'[1]FUSOF AD'!$A:$D,4,0) | Q10: =VLOOKUP(BA$1&$A10,Sheet2!$A:$D,4,0) | R10: =VLOOKUP(BA$1&$A10,Sheet2!$A:$D,4,0) | S10: =VLOOKUP(BA$1&$A10,Sheet2!$A:$D,4,0) | T10: =VLOOKUP(BG$1&$A10,Sheet2!$A:$D,4,0) | AG10: =VLOOKUP(BI$1&$A10,Sheet2!$A:$D,4,0) | AH10: =VLOOKUP(BN$1&$A10,Sheet2!$A:$D,4,0) | AI10: =VLOOKUP(BK$1&$A10,Sheet2!$A:$D,4,0) | AJ10: =VLOOKUP(BL$1&$A10,Sheet2!$A:$D,4,0) | AK10: =VLOOKUP(BB$1&$A10,Sheet2!$A:$D,4,0) | AL10: =VLOOKUP(AZ$1&$A10,Sheet2!$A:$D,4,0) | AN10: =VLOOKUP(BM$1&$A10,Sheet2!$A:$D,4,0) | AO10: 131746.93 | AP10: 1411.7306 | AQ10: 344.40466 | AR10: 570.48222
A11: 44302 | B11: 19251.55 | C11: 20785.61 | D11: 18695.58 | E11: 18695.58 | F11: 18695.58 | G11: 9841.51 | H11: 11045.48 | I11: 8619.95 | J11: 23782.913 | K11: 14966.565 | N11: 1036556.4 | O11: =VLOOKUP(A11,'[1]FUSOF AD'!$A:$D,4,0) | Q11: =VLOOKUP(BA$1&$A11,Sheet2!$A:$D,4,0) | R11: =VLOOKUP(BA$1&$A11,Sheet2!$A:$D,4,0) | S11: =VLOOKUP(BA$1&$A11,Sheet2!$A:$D,4,0) | T11: =VLOOKUP(BG$1&$A11,Sheet2!$A:$D,4,0) | AG11: =VLOOKUP(BI$1&$A11,Sheet2!$A:$D,4,0) | AH11: =VLOOKUP(BN$1&$A11,Sheet2!$A:$D,4,0) | AI11: =VLOOKUP(BK$1&$A11,Sheet2!$A:$D,4,0) | AJ11: =VLOOKUP(BL$1&$A11,Sheet2!$A:$D,4,0) | AK11: =VLOOKUP(BB$1&$A11,Sheet2!$A:$D,4,0) | AL11: =VLOOKUP(AZ$1&$A11,Sheet2!$A:$D,4,0) | AN11: =VLOOKUP(BM$1&$A11,Sheet2!$A:$D,4,0) | AO11: 132388.12 | AP11: 1414.9105 | AQ11: 345.96407 | AR11: 570.23578
A12: 44305 | B12: 18912.3 | C12: 20418.16 | D12: 18359.48 | E12: 18359.48 | F12: 18359.48 | G12: 9661.3 | H12: 10835.62 | I12: 8447.12 | J12: 23352.97 | K12: 14889.084 | N12: 1034818.4 | O12: =VLOOKUP(A12,'[1]FUSOF AD'!$A:$D,4,0) | Q12: =VLOOKUP(BA$1&$A12,Sheet2!$A:$D,4,0) | R12: =VLOOKUP(BA$1&$A12,Sheet2!$A:$D,4,0) | S12: =VLOOKUP(BA$1&$A12,Sheet2!$A:$D,4,0) | T12: =VLOOKUP(BG$1&$A12,Sheet2!$A:$D,4,0) | AG12: =VLOOKUP(BI$1&$A12,Sheet2!$A:$D,4,0) | AH12: =VLOOKUP(BN$1&$A12,Sheet2!$A:$D,4,0) | AI12: =VLOOKUP(BK$1&$A12,Sheet2!$A:$D,4,0) | AJ12: =VLOOKUP(BL$1&$A12,Sheet2!$A:$D,4,0) | AK12: =VLOOKUP(BB$1&$A12,Sheet2!$A:$D,4,0) | AL12: =VLOOKUP(AZ$1&$A12,Sheet2!$A:$D,4,0) | AN12: =VLOOKUP(BM$1&$A12,Sheet2!$A:$D,4,0) | AO12: 132432.86 | AP12: 1391.2856 | AQ12: 337.89082 | AR12: 566.71691
A13: 44306 | B13: 18852.31 | C13: 20328.55 | D13: 18327.47 | E13: 18327.47 | F13: 18327.47 | G13: 9656.7 | H13: 10859.67 | I13: 8511.24 | J13: 23308.938 | K13: 14773.84 | N13: 1028404.8 | O13: =VLOOKUP(A13,'[1]FUSOF AD'!$A:$D,4,0) | Q13: =VLOOKUP(BA$1&$A13,Sheet2!$A:$D,4,0) | R13: =VLOOKUP(BA$1&$A13,Sheet2!$A:$D,4,0) | S13: =VLOOKUP(BA$1&$A13,Sheet2!$A:$D,4,0) | T13: =VLOOKUP(BG$1&$A13,Sheet2!$A:$D,4,0) | AG13: =VLOOKUP(BI$1&$A13,Sheet2!$A:$D,4,0) | AH13: =VLOOKUP(BN$1&$A13,Sheet2!$A:$D,4,0) | AI13: =VLOOKUP(BK$1&$A13,Sheet2!$A:$D,4,0) | AJ13: =VLOOKUP(BL$1&$A13,Sheet2!$A:$D,4,0) | AK13: =VLOOKUP(BB$1&$A13,Sheet2!$A:$D,4,0) | AL13: =VLOOKUP(AZ$1&$A13,Sheet2!$A:$D,4,0) | AN13: =VLOOKUP(BM$1&$A13,Sheet2!$A:$D,4,0) | AO13: 133969.35 | AP13: 1391.2695 | AQ13: 336.45978 | AR13: 562.21569
... A19: 44315 | B19: 19592.13 | C19: 21186.3 | D19: 19058.16 | E19: 19058.16 | F19: 19058.16 | G19: 10032.62 | H19: 11279.03 | I19: 8949.4 | J19: 24234.542 | K19: 14784.826 | N19: 1032784.5 | O19: =VLOOKUP(A19,'[1]FUSOF AD'!$A:$D,4,0) | Q19: =VLOOKUP(BA$1&$A19,Sheet2!$A:$D,4,0) | R19: =VLOOKUP(BA$1&$A19,Sheet2!$A:$D,4,0) | S19: =VLOOKUP(BA$1&$A19,Sheet2!$A:$D,4,0) | T19: =VLOOKUP(BG$1&$A19,Sheet2!$A:$D,4,0) | AG19: =VLOOKUP(BI$1&$A19,Sheet2!$A:$D,4,0) | AH19: =VLOOKUP(BN$1&$A19,Sheet2!$A:$D,4,0) | AI19: =VLOOKUP(BK$1&$A19,Sheet2!$A:$D,4,0) | AJ19: =VLOOKUP(BL$1&$A19,Sheet2!$A:$D,4,0) | AK19: =VLOOKUP(BB$1&$A19,Sheet2!$A:$D,4,0) | AL19: =VLOOKUP(AZ$1&$A19,Sheet2!$A:$D,4,0) | AN19: =VLOOKUP(BM$1&$A19,Sheet2!$A:$D,4,0) | AO19: 131231.42 | AP19: 1448.2895 | AQ19: 350.73289 | AR19: 567.71784
A20: 44316 | B20: 19280.11 | C20: 20811.13 | D20: 18802.03 | E20: 18802.03 | F20: 18802.03 | G20: 9931.2 | H20: 11230.3 | I20: 8922.5 | J20: 23919.821 | K20: 14660.482 | N20: 1025864.3 | O20: =VLOOKUP(A20,'[1]FUSOF AD'!$A:$D,4,0) | Q20: =VLOOKUP(BA$1&$A20,Sheet2!$A:$D,4,0) | R20: =VLOOKUP(BA$1&$A20,Sheet2!$A:$D,4,0) | S20: =VLOOKUP(BA$1&$A20,Sheet2!$A:$D,4,0) | T20: =VLOOKUP(BG$1&$A20,Sheet2!$A:$D,4,0) | AG20: =VLOOKUP(BI$1&$A20,Sheet2!$A:$D,4,0) | AH20: =VLOOKUP(BN$1&$A20,Sheet2!$A:$D,4,0) | AI20: =VLOOKUP(BK$1&$A20,Sheet2!$A:$D,4,0) | AJ20: =VLOOKUP(BL$1&$A20,Sheet2!$A:$D,4,0) | AK20: =VLOOKUP(BB$1&$A20,Sheet2!$A:$D,4,0) | AL20: =VLOOKUP(AZ$1&$A20,Sheet2!$A:$D,4,0) | AN20: 6123.8332 | AO20: 130964.09 | AP20: 1439.052 | AQ20: 348.93729 | AR20: 562.02627
A21: 44319 | B21: 19306.98 | C21: 20815.43 | D21: 18848.97 | E21: 18848.97 | F21: 18848.97 | G21: 9958.46 | H21: 11276.05 | I21: 9037.47 | J21: 23975.269 | K21: 14717.072 | N21: 1020496.8 | O21: =VLOOKUP(A21,'[1]FUSOF AD'!$A:$D,4,0) | Q21: =VLOOKUP(BA$1&$A21,Sheet2!$A:$D,4,0) | R21: =VLOOKUP(BA$1&$A21,Sheet2!$A:$D,4,0) | S21: =VLOOKUP(BA$1&$A21,Sheet2!$A:$D,4,0) | T21: =VLOOKUP(BG$1&$A21,Sheet2!$A:$D,4,0) | AG21: =VLOOKUP(BI$1&$A21,Sheet2!$A:$D,4,0) | AH21: =VLOOKUP(BN$1&$A21,Sheet2!$A:$D,4,0) | AI21: =VLOOKUP(BK$1&$A21,Sheet2!$A:$D,4,0) | AJ21: =VLOOKUP(BL$1&$A21,Sheet2!$A:$D,4,0) | AK21: =VLOOKUP(BB$1&$A21,Sheet2!$A:$D,4,0) | AL21: =VLOOKUP(AZ$1&$A21,Sheet2!$A:$D,4,0) | AN21: 6125.0586 | AO21: 132294.2 | AP21: 1442.6583 | AQ21: 348.83892 | AR21: 561.19816
A22: 44320 | B22: 19140.79 | C22: 20619.62 | D22: 18704.85 | E22: 18704.85 | F22: 18704.85 | G22: 9900.64 | H22: 11241.58 | I22: 8979.59 | J22: 23794.647 | K22: 14586.332 | N22: 1003290.2 | O22: =VLOOKUP(A22,'[1]FUSOF AD'!$A:$D,4,0) | Q22: =VLOOKUP(BA$1&$A22,Sheet2!$A:$D,4,0) | R22: =VLOOKUP(BA$1&$A22,Sheet2!$A:$D,4,0) | S22: =VLOOKUP(BA$1&$A22,Sheet2!$A:$D,4,0) | T22: =VLOOKUP(BG$1&$A22,Sheet2!$A:$D,4,0) | AG22: =VLOOKUP(BI$1&$A22,Sheet2!$A:$D,4,0) | AH22: =VLOOKUP(BN$1&$A22,Sheet2!$A:$D,4,0) | AI22: =VLOOKUP(BK$1&$A22,Sheet2!$A:$D,4,0) | AJ22: =VLOOKUP(BL$1&$A22,Sheet2!$A:$D,4,0) | AK22: =VLOOKUP(BB$1&$A22,Sheet2!$A:$D,4,0) | AL22: =VLOOKUP(AZ$1&$A22,Sheet2!$A:$D,4,0) | AN22: 6126.303 | AO22: 131180.92 | AP22: 1434.2435 | AQ22: 347.00664 | AR22: 555.54039
A23: 44321 | B23: 19322.62 | C23: 20792.24 | D23: 18876.03 | E23: 18876.03 | F23: 18876.03 | G23: 9989.35 | H23: 11336.37 | I23: 9038.56 | J23: 24011.97 | K23: 14744.568 | N23: 999864.37 | O23: =VLOOKUP(A23,'[1]FUSOF AD'!$A:$D,4,0) | Q23: =VLOOKUP(BA$1&$A23,Sheet2!$A:$D,4,0) | R23: =VLOOKUP(BA$1&$A23,Sheet2!$A:$D,4,0) | S23: =VLOOKUP(BA$1&$A23,Sheet2!$A:$D,4,0) | T23: =VLOOKUP(BG$1&$A23,Sheet2!$A:$D,4,0) | AG23: =VLOOKUP(BI$1&$A23,Sheet2!$A:$D,4,0) | AH23: =VLOOKUP(BN$1&$A23,Sheet2!$A:$D,4,0) | AI23: =VLOOKUP(BK$1&$A23,Sheet2!$A:$D,4,0) | AJ23: =VLOOKUP(BL$1&$A23,Sheet2!$A:$D,4,0) | AK23: =VLOOKUP(BB$1&$A23,Sheet2!$A:$D,4,0) | AL23: =VLOOKUP(AZ$1&$A23,Sheet2!$A:$D,4,0) | AN23: 6126.1824 | AO23: 131839.57 | AP23: 1457.7511 | AQ23: 350.33442 | AR23: 556.3771
A24: 44322 | B24: 19459.97 | C24: 20944.41 | D24: 19011.17 | E24: 19011.17 | F24: 19011.17 | G24: 10060.21 | H24: 11416.61 | I24: 9107.61 | J24: 24180.363 | K24: 14918.129 | N24: 1001904.2 | O24: =VLOOKUP(A24,'[1]FUSOF AD'!$A:$D,4,0) | Q24: =VLOOKUP(BA$1&$A24,Sheet2!$A:$D,4,0) | R24: =VLOOKUP(BA$1&$A24,Sheet2!$A:$D,4,0) | S24: =VLOOKUP(BA$1&$A24,Sheet2!$A:$D,4,0) | T24: =VLOOKUP(BG$1&$A24,Sheet2!$A:$D,4,0) | AG24: =VLOOKUP(BI$1&$A24,Sheet2!$A:$D,4,0) | AH24: =VLOOKUP(BN$1&$A24,Sheet2!$A:$D,4,0) | AI24: =VLOOKUP(BK$1&$A24,Sheet2!$A:$D,4,0) | AJ24: =VLOOKUP(BL$1&$A24,Sheet2!$A:$D,4,0) | AK24: =VLOOKUP(BB$1&$A24,Sheet2!$A:$D,4,0) | AL24: =VLOOKUP(AZ$1&$A24,Sheet2!$A:$D,4,0) | AN24: 6127.1225 | AO24: 133597.12 | AP24: 1464.3101 | AQ24: 352.83637 | AR24: 559.68855
A25: 44323 | B25: 19581.29 | C25: 21084.26 | D25: 19104.24 | E25: 19104.24 | F25: 19104.24 | G25: 10074.53 | H25: 11379.24 | I25: 9171.65 | J25: 24297.668 | K25: 14935.828 | N25: 1006591.1 | O25: =VLOOKUP(A25,'[1]FUSOF AD'!$A:$D,4,0) | Q25: =VLOOKUP(BA$1&$A25,Sheet2!$A:$D,4,0) | R25: =VLOOKUP(BA$1&$A25,Sheet2!$A:$D,4,0) | S25: =VLOOKUP(BA$1&$A25,Sheet2!$A:$D,4,0) | T25: =VLOOKUP(BG$1&$A25,Sheet2!$A:$D,4,0) | AG25: =VLOOKUP(BI$1&$A25,Sheet2!$A:$D,4,0) | AH25: =VLOOKUP(BN$1&$A25,Sheet2!$A:$D,4,0) | AI25: =VLOOKUP(BK$1&$A25,Sheet2!$A:$D,4,0) | AJ25: =VLOOKUP(BL$1&$A25,Sheet2!$A:$D,4,0) | AK25: =VLOOKUP(BB$1&$A25,Sheet2!$A:$D,4,0) | AL25: =VLOOKUP(AZ$1&$A25,Sheet2!$A:$D,4,0) | AN25: 6127.726 | AO25: 134086.11 | AP25: 1470.2738 | AQ25: 354.52305 | AR25: 559.84117
A26: 44326 | B26: 19744.24 | C26: 21253.8 | D26: 19266.67 | E26: 19266.67 | F26: 19266.67 | G26: 10148.39 | H26: 11451.29 | I26: 9311.32 | J26: 24508.264 | K26: 14935.114 | N26: 982798.46 | O26: =VLOOKUP(A26,'[1]FUSOF AD'!$A:$D,4,0) | Q26: =VLOOKUP(BA$1&$A26,Sheet2!$A:$D,4,0) | R26: =VLOOKUP(BA$1&$A26,Sheet2!$A:$D,4,0) | S26: =VLOOKUP(BA$1&$A26,Sheet2!$A:$D,4,0) | T26: =VLOOKUP(BG$1&$A26,Sheet2!$A:$D,4,0) | AG26: =VLOOKUP(BI$1&$A26,Sheet2!$A:$D,4,0) | AH26: =VLOOKUP(BN$1&$A26,Sheet2!$A:$D,4,0) | AI26: =VLOOKUP(BK$1&$A26,Sheet2!$A:$D,4,0) | AJ26: =VLOOKUP(BL$1&$A26,Sheet2!$A:$D,4,0) | AK26: =VLOOKUP(BB$1&$A26,Sheet2!$A:$D,4,0) | AL26: =VLOOKUP(AZ$1&$A26,Sheet2!$A:$D,4,0) | AN26: 6128.9457 | AO26: 134813.06 | AP26: 1487.334 | AQ26: 359.35077 | AR26: 554.60166
A27: 44327 | B27: 19646.5 | C27: 21123.53 | D27: 19225.1 | E27: 19225.1 | F27: 19225.1 | G27: 10164.36 | H27: 11544.85 | I27: 9388.49 | J27: 24458.394 | K27: 14835.403 | N27: 980319.84 | O27: =VLOOKUP(A27,'[1]FUSOF AD'!$A:$D,4,0) | Q27: =VLOOKUP(BA$1&$A27,Sheet2!$A:$D,4,0) | R27: =VLOOKUP(BA$1&$A27,Sheet2!$A:$D,4,0) | S27: =VLOOKUP(BA$1&$A27,Sheet2!$A:$D,4,0) | T27: =VLOOKUP(BG$1&$A27,Sheet2!$A:$D,4,0) | AG27: =VLOOKUP(BI$1&$A27,Sheet2!$A:$D,4,0) | AH27: =VLOOKUP(BN$1&$A27,Sheet2!$A:$D,4,0) | AI27: =VLOOKUP(BK$1&$A27,Sheet2!$A:$D,4,0) | AJ27: =VLOOKUP(BL$1&$A27,Sheet2!$A:$D,4,0) | AK27: =VLOOKUP(BB$1&$A27,Sheet2!$A:$D,4,0) | AL27: =VLOOKUP(AZ$1&$A27,Sheet2!$A:$D,4,0) | AN27: 6129.5429 | AO27: 134776.28 | AP27: 1492.1922 | AQ27: 362.53795 | AR27: 550.07685
A28: 44328 | B28: 19475.21 | C28: 20904.13 | D28: 19066.54 | E28: 19066.54 | F28: 19066.54 | G28: 10087.63 | H28: 11471.2 | I28: 9323.53 | J28: 24258.461 | K28: 14736.3 | N28: 956233.09 | O28: =VLOOKUP(A28,'[1]FUSOF AD'!$A:$D,4,0) | Q28: =VLOOKUP(BA$1&$A28,Sheet2!$A:$D,4,0) | R28: =VLOOKUP(BA$1&$A28,Sheet2!$A:$D,4,0) | S28: =VLOOKUP(BA$1&$A28,Sheet2!$A:$D,4,0) | T28: =VLOOKUP(BG$1&$A28,Sheet2!$A:$D,4,0) | AG28: =VLOOKUP(BI$1&$A28,Sheet2!$A:$D,4,0) | AH28: =VLOOKUP(BN$1&$A28,Sheet2!$A:$D,4,0) | AI28: =VLOOKUP(BK$1&$A28,Sheet2!$A:$D,4,0) | AJ28: =VLOOKUP(BL$1&$A28,Sheet2!$A:$D,4,0) | AK28: =VLOOKUP(BB$1&$A28,Sheet2!$A:$D,4,0) | AL28: =VLOOKUP(AZ$1&$A28,Sheet2!$A:$D,4,0) | AN28: 6130.2861 | AO28: 133489.3 | AP28: 1481.102 | AQ28: 361.06134 | AR28: 542.58243
A29: 44330 | B29: 19414.21 | C29: 20877.56 | D29: 18966.49 | E29: 18966.49 | F29: 18966.49 | G29: 9998.36 | H29: 11304.37 | I29: 9232.36 | J29: 24129.987 | K29: 14608.993 | N29: 981931.41 | O29: =VLOOKUP(A29,'[1]FUSOF AD'!$A:$D,4,0) | Q29: =VLOOKUP(BA$1&$A29,Sheet2!$A:$D,4,0) | R29: =VLOOKUP(BA$1&$A29,Sheet2!$A:$D,4,0) | S29: =VLOOKUP(BA$1&$A29,Sheet2!$A:$D,4,0) | T29: =VLOOKUP(BG$1&$A29,Sheet2!$A:$D,4,0) | AG29: =VLOOKUP(BI$1&$A29,Sheet2!$A:$D,4,0) | AH29: =VLOOKUP(BN$1&$A29,Sheet2!$A:$D,4,0) | AI29: =VLOOKUP(BK$1&$A29,Sheet2!$A:$D,4,0) | AJ29: =VLOOKUP(BL$1&$A29,Sheet2!$A:$D,4,0) | AK29: =VLOOKUP(BB$1&$A29,Sheet2!$A:$D,4,0) | AL29: =VLOOKUP(AZ$1&$A29,Sheet2!$A:$D,4,0) | AN29: 6131.8242 | AO29: 135014.11 | AP29: 1468.6112 | AQ29: 357.10891 | AR29: 541.80332
A30: 44333 | B30: 19728.31 | C30: 21226.53 | D30: 19270.53 | E30: 19270.53 | F30: 19270.53 | G30: 10162.08 | H30: 11491.7 | I30: 9351.65 | J30: 24518.072 | K30: 14663.357 | N30: 976327.79 | O30: =VLOOKUP(A30,'[1]FUSOF AD'!$A:$D,4,0) | Q30: =VLOOKUP(BA$1&$A30,Sheet2!$A:$D,4,0) | R30: =VLOOKUP(BA$1&$A30,Sheet2!$A:$D,4,0) | S30: =VLOOKUP(BA$1&$A30,Sheet2!$A:$D,4,0) | T30: =VLOOKUP(BG$1&$A30,Sheet2!$A:$D,4,0) | AG30: =VLOOKUP(BI$1&$A30,Sheet2!$A:$D,4,0) | AH30: =VLOOKUP(BN$1&$A30,Sheet2!$A:$D,4,0) | AI30: =VLOOKUP(BK$1&$A30,Sheet2!$A:$D,4,0) | AJ30: =VLOOKUP(BL$1&$A30,Sheet2!$A:$D,4,0) | AK30: =VLOOKUP(BB$1&$A30,Sheet2!$A:$D,4,0) | AL30: =VLOOKUP(AZ$1&$A30,Sheet2!$A:$D,4,0) | AN30: 6133.776 | AO30: 136843.49 | AP30: 1490.2404 | AQ30: 364.09291 | AR30: 542.56643
A31: 44334 | B31: 19977.08 | C31: 21489.56 | D31: 19524.65 | E31: 19524.65 | F31: 19524.65 | G31: 10310.21 | H31: 11681.99 | I31: 9468.79 | J31: 24841.063 | K31: 14739.789 | N31: 968400.24 | O31: =VLOOKUP(A31,'[1]FUSOF AD'!$A:$D,4,0) | Q31: =VLOOKUP(BA$1&$A31,Sheet2!$A:$D,4,0) | R31: =VLOOKUP(BA$1&$A31,Sheet2!$A:$D,4,0) | S31: =VLOOKUP(BA$1&$A31,Sheet2!$A:$D,4,0) | T31: =VLOOKUP(BG$1&$A31,Sheet2!$A:$D,4,0) | AG31: =VLOOKUP(BI$1&$A31,Sheet2!$A:$D,4,0) | AH31: =VLOOKUP(BN$1&$A31,Sheet2!$A:$D,4,0) | AI31: =VLOOKUP(BK$1&$A31,Sheet2!$A:$D,4,0) | AJ31: =VLOOKUP(BL$1&$A31,Sheet2!$A:$D,4,0) | AK31: =VLOOKUP(BB$1&$A31,Sheet2!$A:$D,4,0) | AL31: =VLOOKUP(AZ$1&$A31,Sheet2!$A:$D,4,0) | AN31: 6134.1129 | AO31: 136473.47 | AP31: 1502.8896 | AQ31: 367.95532 | AR31: 547.36548
... A39: 44344 | B39: 20406.65 | C39: 21962.31 | D39: 19952.29 | E39: 19952.29 | F39: 19952.29 | G39: 10520.35 | H39: 11906.95 | I39: 9784.17 | J39: 25372.27 | K39: 15251.683 | N39: 988272.62 | O39: =VLOOKUP(A39,'[1]FUSOF AD'!$A:$D,4,0) | Q39: =VLOOKUP(BA$1&$A39,Sheet2!$A:$D,4,0) | R39: =VLOOKUP(BA$1&$A39,Sheet2!$A:$D,4,0) | S39: =VLOOKUP(BA$1&$A39,Sheet2!$A:$D,4,0) | T39: =VLOOKUP(BG$1&$A39,Sheet2!$A:$D,4,0) | AG39: =VLOOKUP(BI$1&$A39,Sheet2!$A:$D,4,0) | AH39: =VLOOKUP(BN$1&$A39,Sheet2!$A:$D,4,0) | AI39: =VLOOKUP(BK$1&$A39,Sheet2!$A:$D,4,0) | AJ39: =VLOOKUP(BL$1&$A39,Sheet2!$A:$D,4,0) | AK39: =VLOOKUP(BB$1&$A39,Sheet2!$A:$D,4,0) | AL39: =VLOOKUP(AZ$1&$A39,Sheet2!$A:$D,4,0) | AN39: 6140.8197 | AO39: 137751.14 | AP39: 1543.7038 | AQ39: 377.53797 | AR39: 566.30965
A40: 44347 | B40: 20625.45 | C40: 22203.59 | D40: 20138.1 | E40: 20138.1 | F40: 20138.1 | G40: 10598.29 | H40: 11955.56 | I40: 9824.52 | J40: 25611.582 | K40: 15314.804 | Q40: =VLOOKUP(BA$1&$A40,Sheet2!$A:$D,4,0) | R40: =VLOOKUP(BA$1&$A40,Sheet2!$A:$D,4,0) | S40: =VLOOKUP(BA$1&$A40,Sheet2!$A:$D,4,0) | T40: =VLOOKUP(BG$1&$A40,Sheet2!$A:$D,4,0) | AG40: =VLOOKUP(BI$1&$A40,Sheet2!$A:$D,4,0) | AH40: =VLOOKUP(BN$1&$A40,Sheet2!$A:$D,4,0) | AI40: =VLOOKUP(BK$1&$A40,Sheet2!$A:$D,4,0) | AJ40: =VLOOKUP(BL$1&$A40,Sheet2!$A:$D,4,0) | AK40: =VLOOKUP(BB$1&$A40,Sheet2!$A:$D,4,0) | AL40: =VLOOKUP(AZ$1&$A40,Sheet2!$A:$D,4,0) | AN40: 6141.7492 | AO40: 138232.07 | AP40: 1557.001 | AQ40: 380.63122 | AR40: 568.06489
A41: 44348 | B41: 20613.31 | C41: 22192.25 | D41: 20113.79 | E41: 20113.79 | F41: 20113.79 | G41: 10585.13 | H41: 11932.83 | I41: 9758.89 | J41: 25584.42 | K41: 15300.74 | N41: 990701.72 | O41: 636773.9 | Q41: =VLOOKUP(BA$1&$A41,Sheet2!$A:$D,4,0) | R41: =VLOOKUP(BA$1&$A41,Sheet2!$A:$D,4,0) | S41: =VLOOKUP(BA$1&$A41,Sheet2!$A:$D,4,0) | T41: =VLOOKUP(BG$1&$A41,Sheet2!$A:$D,4,0) | AG41: =VLOOKUP(BI$1&$A41,Sheet2!$A:$D,4,0) | AH41: =VLOOKUP(BN$1&$A41,Sheet2!$A:$D,4,0) | AI41: =VLOOKUP(BK$1&$A41,Sheet2!$A:$D,4,0) | AJ41: =VLOOKUP(BL$1&$A41,Sheet2!$A:$D,4,0) | AK41: =VLOOKUP(BB$1&$A41,Sheet2!$A:$D,4,0) | AL41: =VLOOKUP(AZ$1&$A41,Sheet2!$A:$D,4,0) | AN41: 6142.3541 | AO41: 138447.84 | AP41: 1552.9914 | AQ41: 380.70292 | AR41: 568.61316
A42: 44349 | B42: 20669.16 | C42: 22194.18 | D42: 20210.99 | E42: 20210.99 | F42: 20210.99 | G42: 10667.69 | H42: 12087.28 | I42: 9878.31 | J42: 25710.645 | K42: 15214.576 | N42: 994800.73 | O42: 639391.38 | Q42: =VLOOKUP(BA$1&$A42,Sheet2!$A:$D,4,0) | R42: =VLOOKUP(BA$1&$A42,Sheet2!$A:$D,4,0) | S42: =VLOOKUP(BA$1&$A42,Sheet2!$A:$D,4,0) | T42: =VLOOKUP(BG$1&$A42,Sheet2!$A:$D,4,0) | AG42: =VLOOKUP(BI$1&$A42,Sheet2!$A:$D,4,0) | AH42: =VLOOKUP(BN$1&$A42,Sheet2!$A:$D,4,0) | AI42: =VLOOKUP(BK$1&$A42,Sheet2!$A:$D,4,0) | AJ42: =VLOOKUP(BL$1&$A42,Sheet2!$A:$D,4,0) | AK42: =VLOOKUP(BB$1&$A42,Sheet2!$A:$D,4,0) | AL42: =VLOOKUP(AZ$1&$A42,Sheet2!$A:$D,4,0) | AN42: 6142.7106 | AO42: 139184.51 | AP42: 1558.2927 | AQ42: 383.16985 | AR42: 567.67264
A43: 44350 | B43: 20830.44 | C43: 22361.86 | D43: 20376.14 | E43: 20376.14 | F43: 20376.14 | G43: 10755.78 | H43: 12192.59 | I43: 9991.13 | J43: 25918.84 | K43: 15283.609 | N43: 984166.89 | O43: 635638.53 | Q43: =VLOOKUP(BA$1&$A43,Sheet2!$A:$D,4,0) | R43: =VLOOKUP(BA$1&$A43,Sheet2!$A:$D,4,0) | S43: =VLOOKUP(BA$1&$A43,Sheet2!$A:$D,4,0) | T43: =VLOOKUP(BG$1&$A43,Sheet2!$A:$D,4,0) | AG43: =VLOOKUP(BI$1&$A43,Sheet2!$A:$D,4,0) | AH43: =VLOOKUP(BN$1&$A43,Sheet2!$A:$D,4,0) | AI43: =VLOOKUP(BK$1&$A43,Sheet2!$A:$D,4,0) | AJ43: =VLOOKUP(BL$1&$A43,Sheet2!$A:$D,4,0) | AK43: =VLOOKUP(BB$1&$A43,Sheet2!$A:$D,4,0) | AL43: =VLOOKUP(AZ$1&$A43,Sheet2!$A:$D,4,0) | AN43: 6143.3604 | AO43: 136626.43 | AP43: 1569.7665 | AQ43: 386.66713 | AR43: 567.49241
A44: 44351 | B44: 20821.55 | C44: 22333.23 | D44: 20396.67 | E44: 20396.67 | F44: 20396.67 | G44: 10789.79 | H44: 12274.86 | I44: 10042.92 | J44: 25945.664 | K44: 15286.002 | N44: 998851.97 | O44: 642040.84 | Q44: =VLOOKUP(BA$1&$A44,Sheet2!$A:$D,4,0) | R44: =VLOOKUP(BA$1&$A44,Sheet2!$A:$D,4,0) | S44: =VLOOKUP(BA$1&$A44,Sheet2!$A:$D,4,0) | T44: =VLOOKUP(BG$1&$A44,Sheet2!$A:$D,4,0) | AG44: =VLOOKUP(BI$1&$A44,Sheet2!$A:$D,4,0) | AH44: =VLOOKUP(BN$1&$A44,Sheet2!$A:$D,4,0) | AI44: =VLOOKUP(BK$1&$A44,Sheet2!$A:$D,4,0) | AJ44: =VLOOKUP(BL$1&$A44,Sheet2!$A:$D,4,0) | AK44: =VLOOKUP(BB$1&$A44,Sheet2!$A:$D,4,0) | AL44: =VLOOKUP(AZ$1&$A44,Sheet2!$A:$D,4,0) | AN44: 6144.5901 | AO44: 137703.21 | AP44: 1566.4683 | AQ44: 389.1274 | AR44: 569.17664
A45: 44354 | B45: 20916.57 | C45: 22449.24 | D45: 20527.27 | E45: 20527.27 | F45: 20527.27 | G45: 10881.61 | H45: 12427.38 | I45: 10189.9 | J45: 26109.355 | K45: 15428.302 | N45: 1000514 | O45: 639874.67 | Q45: =VLOOKUP(BA$1&$A45,Sheet2!$A:$D,4,0) | R45: =VLOOKUP(BA$1&$A45,Sheet2!$A:$D,4,0) | S45: =VLOOKUP(BA$1&$A45,Sheet2!$A:$D,4,0) | T45: =VLOOKUP(BG$1&$A45,Sheet2!$A:$D,4,0) | AG45: =VLOOKUP(BI$1&$A45,Sheet2!$A:$D,4,0) | AH45: =VLOOKUP(BN$1&$A45,Sheet2!$A:$D,4,0) | AI45: =VLOOKUP(BK$1&$A45,Sheet2!$A:$D,4,0) | AJ45: =VLOOKUP(BL$1&$A45,Sheet2!$A:$D,4,0) | AK45: =VLOOKUP(BB$1&$A45,Sheet2!$A:$D,4,0) | AL45: =VLOOKUP(AZ$1&$A45,Sheet2!$A:$D,4,0) | AN45: 6146.3996 | AO45: 138220.34 | AP45: 1577.5208 | AQ45: 393.56111 | AR45: 572.27246
A46: 44355 | B46: 20914.76 | C46: 22432.77 | D46: 20553.02 | E46: 20553.02 | F46: 20553.02 | G46: 10916.27 | H46: 12506.96 | I46: 10241.89 | J46: 26147.802 | K46: 15634.272 | N46: 1003550 | O46: 640691.67 | Q46: =VLOOKUP(BA$1&$A46,Sheet2!$A:$D,4,0) | R46: =VLOOKUP(BA$1&$A46,Sheet2!$A:$D,4,0) | S46: =VLOOKUP(BA$1&$A46,Sheet2!$A:$D,4,0) | T46: =VLOOKUP(BG$1&$A46,Sheet2!$A:$D,4,0) | AG46: =VLOOKUP(BI$1&$A46,Sheet2!$A:$D,4,0) | AH46: =VLOOKUP(BN$1&$A46,Sheet2!$A:$D,4,0) | AI46: =VLOOKUP(BK$1&$A46,Sheet2!$A:$D,4,0) | AJ46: =VLOOKUP(BL$1&$A46,Sheet2!$A:$D,4,0) | AK46: =VLOOKUP(BB$1&$A46,Sheet2!$A:$D,4,0) | AL46: =VLOOKUP(AZ$1&$A46,Sheet2!$A:$D,4,0) | AN46: 6146.425 | AO46: 138081.21 | AP46: 1576.825 | AQ46: 395.66236 | AR46: 578.12465
A47: 44356 | B47: 20767.88 | C47: 22283.52 | D47: 20400.55 | E47: 20400.55 | F47: 20400.55 | G47: 10838.36 | H47: 12416.31 | I47: 10115.99 | J47: 25954.321 | K47: 15583.437 | N47: 1004505.1 | O47: 640327.21 | Q47: =VLOOKUP(BA$1&$A47,Sheet2!$A:$D,4,0) | R47: =VLOOKUP(BA$1&$A47,Sheet2!$A:$D,4,0) | S47: =VLOOKUP(BA$1&$A47,Sheet2!$A:$D,4,0) | T47: =VLOOKUP(BG$1&$A47,Sheet2!$A:$D,4,0) | AG47: =VLOOKUP(BI$1&$A47,Sheet2!$A:$D,4,0) | AH47: =VLOOKUP(BN$1&$A47,Sheet2!$A:$D,4,0) | AI47: =VLOOKUP(BK$1&$A47,Sheet2!$A:$D,4,0) | AJ47: =VLOOKUP(BL$1&$A47,Sheet2!$A:$D,4,0) | AK47: =VLOOKUP(BB$1&$A47,Sheet2!$A:$D,4,0) | AL47: =VLOOKUP(AZ$1&$A47,Sheet2!$A:$D,4,0) | AN47: 6146.699 | AO47: 137808.01 | AP47: 1565.8908 | AQ47: 392.12785 | AR47: 577.06011
A48: 44357 | B48: 20935.83 | C48: 22448.94 | D48: 20596.64 | E48: 20596.64 | F48: 20596.64 | G48: 10962.32 | H48: 12599.02 | I48: 10279.31 | J48: 26205.712 | K48: 15718.462 | N48: 1015874.6 | O48: 644064.81 | Q48: =VLOOKUP(BA$1&$A48,Sheet2!$A:$D,4,0) | R48: =VLOOKUP(BA$1&$A48,Sheet2!$A:$D,4,0) | S48: =VLOOKUP(BA$1&$A48,Sheet2!$A:$D,4,0) | T48: =VLOOKUP(BG$1&$A48,Sheet2!$A:$D,4,0) | AG48: =VLOOKUP(BI$1&$A48,Sheet2!$A:$D,4,0) | AH48: =VLOOKUP(BN$1&$A48,Sheet2!$A:$D,4,0) | AI48: =VLOOKUP(BK$1&$A48,Sheet2!$A:$D,4,0) | AJ48: =VLOOKUP(BL$1&$A48,Sheet2!$A:$D,4,0) | AK48: =VLOOKUP(BB$1&$A48,Sheet2!$A:$D,4,0) | AL48: =VLOOKUP(AZ$1&$A48,Sheet2!$A:$D,4,0) | AN48: 6146.8265 | AO48: 138696.91 | AP48: 1577.4474 | AQ48: 395.52343 | AR48: 581.53052
A49: 44358 | B49: 21017.72 | C49: 22544.26 | D49: 20672.33 | E49: 20672.33 | F49: 20672.33 | G49: 10997.29 | H49: 12630.36 | I49: 10316.45 | J49: 26303.871 | K49: 15904.183 | N49: 1019348.4 | O49: 645477.69 | Q49: =VLOOKUP(BA$1&$A49,Sheet2!$A:$D,4,0) | R49: =VLOOKUP(BA$1&$A49,Sheet2!$A:$D,4,0) | S49: =VLOOKUP(BA$1&$A49,Sheet2!$A:$D,4,0) | T49: =VLOOKUP(BG$1&$A49,Sheet2!$A:$D,4,0) | AG49: =VLOOKUP(BI$1&$A49,Sheet2!$A:$D,4,0) | AH49: =VLOOKUP(BN$1&$A49,Sheet2!$A:$D,4,0) | AI49: =VLOOKUP(BK$1&$A49,Sheet2!$A:$D,4,0) | AJ49: =VLOOKUP(BL$1&$A49,Sheet2!$A:$D,4,0) | AK49: =VLOOKUP(BB$1&$A49,Sheet2!$A:$D,4,0) | AL49: =VLOOKUP(AZ$1&$A49,Sheet2!$A:$D,4,0) | AN49: 6148.8349 | AO49: 137445.11 | AP49: 1574.9745 | AQ49: 396.2559 | AR49: 586.86724
A50: 44361 | B50: 21021.81 | C50: 22567.11 | D50: 20660.97 | E50: 20660.97 | F50: 20660.97 | G50: 10983.3 | H50: 12596.29 | I50: 10267.27 | J50: 26291.421 | K50: 15966.118 | N50: 1030566 | O50: 648557.98 | Q50: =VLOOKUP(BA$1&$A50,Sheet2!$A:$D,4,0) | R50: =VLOOKUP(BA$1&$A50,Sheet2!$A:$D,4,0) | S50: =VLOOKUP(BA$1&$A50,Sheet2!$A:$D,4,0) | T50: =VLOOKUP(BG$1&$A50,Sheet2!$A:$D,4,0) | AG50: =VLOOKUP(BI$1&$A50,Sheet2!$A:$D,4,0) | AH50: =VLOOKUP(BN$1&$A50,Sheet2!$A:$D,4,0) | AI50: =VLOOKUP(BK$1&$A50,Sheet2!$A:$D,4,0) | AJ50: =VLOOKUP(BL$1&$A50,Sheet2!$A:$D,4,0) | AK50: =VLOOKUP(BB$1&$A50,Sheet2!$A:$D,4,0) | AL50: =VLOOKUP(AZ$1&$A50,Sheet2!$A:$D,4,0) | AN50: 6150.059 | AO50: 136553.51 | AP50: 1574.3152 | AQ50: 395.94802 | AR50: 589.32297
A51: 44362 | B51: 21096.29 | C51: 22649.05 | D51: 20742.75 | E51: 20742.75 | F51: 20742.75 | G51: 11034.36 | H51: 12668.44 | I51: 10318.38 | J51: 26393.929 | K51: 16025.187 | N51: 1024696.4 | O51: 647641.25 | Q51: =VLOOKUP(BA$1&$A51,Sheet2!$A:$D,4,0) | R51: =VLOOKUP(BA$1&$A51,Sheet2!$A:$D,4,0) | S51: =VLOOKUP(BA$1&$A51,Sheet2!$A:$D,4,0) | T51: =VLOOKUP(BG$1&$A51,Sheet2!$A:$D,4,0) | AG51: =VLOOKUP(BI$1&$A51,Sheet2!$A:$D,4,0) | AH51: =VLOOKUP(BN$1&$A51,Sheet2!$A:$D,4,0) | AI51: =VLOOKUP(BK$1&$A51,Sheet2!$A:$D,4,0) | AJ51: =VLOOKUP(BL$1&$A51,Sheet2!$A:$D,4,0) | AK51: =VLOOKUP(BB$1&$A51,Sheet2!$A:$D,4,0) | AL51: =VLOOKUP(AZ$1&$A51,Sheet2!$A:$D,4,0) | AN51: 6150.6711 | AO51: 136335.27 | AP51: 1579.4488 | AQ51: 397.89033 | AR51: 591.95573
A52: 44363 | B52: 20951.23 | C52: 22503.9 | D52: 20595.05 | E52: 20595.05 | F52: 20595.05 | G52: 10947.71 | H52: 12556.91 | I52: 10255.52 | J52: 26206.577 | K52: 16040.681 | N52: 1021213.2 | O52: 644257.19 | Q52: =VLOOKUP(BA$1&$A52,Sheet2!$A:$D,4,0) | R52: =VLOOKUP(BA$1&$A52,Sheet2!$A:$D,4,0) | S52: =VLOOKUP(BA$1&$A52,Sheet2!$A:$D,4,0) | T52: =VLOOKUP(BG$1&$A52,Sheet2!$A:$D,4,0) | AG52: =VLOOKUP(BI$1&$A52,Sheet2!$A:$D,4,0) | AH52: =VLOOKUP(BN$1&$A52,Sheet2!$A:$D,4,0) | AI52: =VLOOKUP(BK$1&$A52,Sheet2!$A:$D,4,0) | AJ52: =VLOOKUP(BL$1&$A52,Sheet2!$A:$D,4,0) | AK52: =VLOOKUP(BB$1&$A52,Sheet2!$A:$D,4,0) | AL52: =VLOOKUP(AZ$1&$A52,Sheet2!$A:$D,4,0) | AN52: 6147.8849 | AO52: 132761.76 | AP52: 1570.1103 | AQ52: 394.79874 | AR52: 593.37372
...

Sheet Sheet2
B1: Index | C1: Index Date | D1: Index Value
A2: =B2&C2 | B2: CRISIL 10 Year Gilt Index | C2: 46080 | D2: 5207.282
A3: =B3&C3 | B3: CRISIL 10 Year Gilt Index | C3: 46081 | D3: 5210.1311
A4: =B4&C4 | B4: CRISIL 10 Year Gilt Index | C4: 46082 | D4: 5211.0774
A5: =B5&C5 | B5: CRISIL 10 Year Gilt Index | C5: 46083 | D5: 5207.7243
A6: =B6&C6 | B6: CRISIL 10 Year Gilt Index | C6: 46084 | D6: 5208.6705
A7: =B7&C7 | B7: CRISIL 10 Year Gilt Index | C7: 46085 | D7: 5207.8631
A8: =B8&C8 | B8: CRISIL 10 Year Gilt Index | C8: 46086 | D8: 5221.7282
A9: =B9&C9 | B9: CRISIL 10 Year Gilt Index | C9: 46087 | D9: 5206.1043
A10: =B10&C10 | B10: CRISIL 10 Year Gilt Index | C10: 46088 | D10: 5207.0557
A11: =B11&C11 | B11: CRISIL 10 Year Gilt Index | C11: 46089 | D11: 5208.0123
A12: =B12&C12 | B12: CRISIL 10 Year Gilt Index | C12: 46090 | D12: 5197.958
A13: =B13&C13 | B13: CRISIL 10 Year Gilt Index | C13: 46091 | D13: 5219.383
... A1737: =B1737&C1737 | B1737: NIFTY Ultra Short Duration Debt Index A-I | C1737: 46112 | D1737: 5717.31
A1738: =B1738&C1738
A1739: =B1739&C1739
A1740: =B1740&C1740
A1741: =B1741&C1741
A1742: =B1742&C1742
A1743: =B1743&C1743
A1744: =B1744&C1744
A1745: =B1745&C1745
A1746: =B1746&C1746
A1747: =B1747&C1747
A1748: =B1748&C1748
A1749: =B1749&C1749
... A4689: =B4689&C4689

Sheet Sheet3
A1: Date | B1: Franklin_FIMAAF
A2: 45869 | B2: 1000
A3: 45870 | B3: 993.00774
A4: 45873 | B4: 1000.8869
A5: 45874 | B5: 999.59829
A6: 45875 | B6: 996.47348
A7: 45876 | B7: 998.10786
A8: 45877 | B8: 991.40588
A9: 45880 | B9: 995.25336
A10: 45881 | B10: 993.32418
A11: 45882 | B11: 997.94497
A12: 45883 | B12: 997.57945
A13: 45887 | B13: 1003.9847
... A165: 46111 | B165: 1026.5762

Sheet Sheet4
A1: Date | B1: Franklin_CRISIL_1_Year_T-Bill_Index
A2: 46023 | B2: 7963.0177
A3: 46024 | B3: 7964.1506
A4: 46025 | B4: 7965.2919
A5: 46026 | B5: 7966.4333
A6: 46027 | B6: 7968.3131
A7: 46028 | B7: 7967.2641
A8: 46029 | B8: 7965.1325
A9: 46030 | B9: 7963.6618
A10: 46031 | B10: 7964.998
A11: 46032 | B11: 7966.1494
A12: 46033 | B12: 7967.3007
A13: 46034 | B13: 7968.8218
... A32: 46053 | B32: 7972.8436
